Workbook

Sheet Summary (All 189)
A1: TC ID | B1: Rule ID | C1: Topic | D1: Priority | E1: Verdict | F1: Automated? | G1: Explanation | H1: Related Bug(s) (bug log v10)
A2: TC-BR-131 | B2: BR-131 | C2: Contradiction - Batch | D2: P1 - Critical | E2: PASS | F2: Yes | G2: [OK] run still reports COMPLETED despite the blocked master write (silent failure) | [OK] source-of-truth (pru_adb.contract) row WAS created - the failure is specific to the master-write step | [OK] adsi_master.contract_record has NO row for this subject - the blocked write never landed | [OK] master_control.last_updated_date did not advance past its pre-run value | [OK] an ERROR-level log line related to the failed sync was emitted
A3: TC-BR-304 | B3: BR-304 | C3: Validation - Appointment Consistency | D3: P1 - Critical | E3: PASS | F3: Yes | G3: [OK] the move to active writes RA00RA, and node_relationship confirms status 'A' | [OK] the move away from active writes TE00TE, and node_relationship confirms status 'T' | [OK] both transitions are also visible on the master side after HR2 runs: the activated producer's status_code is A and the terminated producer's is T
A4: TC-BR-391 | B4: BR-391 | C4: Validation - Comparison Fields | D4: P1 - Critical | E4: PASS | F4: Yes | G4: [OK] org_elimination_date on the newly built master record differs from the previously-stored value once a real termination date is fed
A5: TC-BR-412 | B5: BR-412 | C5: Validation - Comparison Fields | D5: P1 - Critical | E5: PASS | F5: Yes | G5: [OK] adsi_master.contract_record.final_date now equals the new relationship end date, differing from the pre-termination value
A6: TC-BR-447 | B6: BR-447 | C6: Validation - Table Integrity | D6: P1 - Critical | E6: PASS | F6: Yes | G6: [OK] adsi_master.organization_record.org_status = '9' (eliminated) after terminating the firm's profile | [OK] org_elimination_date is populated and differs from the pre-termination value
A7: TC-BR-464 | B7: BR-464 | C7: Validation - Entity Type Rules | D7: P1 - Critical | E7: PASS | F7: Yes | G7: [OK] terminated-with-date subject has both final_org_code and final_date populated | [OK] inactive-without-date subject (DB-seeded status=I, end date=NULL, then HR2-rebuilt) has final_org_code but NULL final_date | H7: DEF-RDMS-BRV4-005 - Not a defect; Closed - QA retest PASS
A8: TC-BR-476 | B8: BR-476 | C8: Validation - Master Action Routing | D8: P1 - Critical | E8: PASS | F8: Yes | G8: [OK] run with no activity still completes gracefully (not an error) | [OK] master_control.last_updated_date is unchanged or has advanced (never regressed/nulled) by a no-activity cycle
A9: TC-BR-482 | B9: BR-482 | C9: Validation - Master Action Routing | D9: P1 - Critical | E9: PASS | F9: Yes | G9: [OK] this firm's own organization_record/contract_record master rows exist at all in adsi_master (checked right after the first, real feed upload, before any DB-seeding) - previously found missing due to a since-fixed poison-row issue (DEF-RDMS-BRV4-013) | [OK] org entry landed in organization_record | [OK] contract entry landed in contract_record | H9: DEF-RDMS-BRV4-013 - Not a defect (test data); Closed - retracted by QA
A10: TC-BR-485 | B10: BR-485 | C10: Validation - Master File Status | D10: P1 - Critical | E10: PASS | F10: Yes | G10: [OK] both contracts sharing the TIN are present in the master
A11: TC-BR-486 | B11: BR-486 | C11: Validation - Master File Status | D11: P1 - Critical | E11: PASS | F11: Yes | G11: [OK] only firm A's own contract_record row changes - firm B's is untouched, proving the shared TIN never causes cross-contamination on an update
A12: TC-BR-125 | B12: BR-125 | C12: Transaction Integrity | D12: P1 - Critical | E12: PASS | F12: Yes | G12: [OK] the faulted bundle is rejected wholesale | [OK] the faulted bundle's BD identifier appears in LNAERROR | [OK] first producer of the failing bundle is set aside with reason 002, not independently rejected | [OK] second producer of the failing bundle is set aside with reason 002, not independently rejected | [OK] the control bundle's producer is committed, proving the failure did not spill over
A13: TC-BR-126 | B13: BR-126 | C13: Transaction Integrity | D13: P1 - Critical | E13: PASS | F13: Yes | G13: [OK] the GOOD standalone record (existing parent on file) is committed: contract row exists, personal field update applied | [OK] the BAD standalone record (parent never on file) leaves no rows at all - rejected on its own merits, independent of the good record | [OK] run log shows all 4 standalone records processed (no whole-file no-op); no INFO-level log line calls out the rejection specifically, though the DB outcome above is correct
A14: TC-BR-128 | B14: BR-128 | C14: Outcome Classification | D14: P1 - Critical | E14: PASS | F14: Yes | G14: [OK] the own-merits-bad producer (D01, SSN 000000000) is refused and appears in LNAERROR | [OK] that producer's D02 is consequentially set aside with reason 002 (not its own fault), distinguishable from the D01's own-merits rejection | [OK] the separate BD (reserved TIN) is refused on its own merits and appears in LNAERROR | [OK] that BD's own-merits rejection is in LNAERROR only, never ADBSKIP - the three outcomes stay distinguishable
A15: TC-BR-134 | B15: BR-134 | C15: Appointment and Relationship | D15: P1 - Critical | E15: PASS | F15: Yes | G15: [OK] day1 (real appointment under firm X) committed | [OK] the real appointment under firm X exists (precondition) | [OK] BA decision pending (DEF-RDMS-BRV4-002): whether a type-H profile under firm Y creates its own live contract row for an already-appointed person - reported factually, not asserted right/wrong | H15: DEF-RDMS-BRV4-002 - Spec conflict; Blocked - BA decision
A16: TC-BR-142 | B16: BR-142 | C16: Identifier Generation | D16: P1 - Critical | E16: PASS | F16: Yes | G16: [OK] run completed despite the seeded collision (no retry loop hang/error)
A17: TC-BR-143 | B17: BR-143 | C17: Identifier Generation | D17: P1 - Critical | E17: PASS | F17: Yes | G17: [OK] pru_contract_number is 6 chars: fixed leading char + 5 from the no-vowel/no-zero alphabet
A18: TC-BR-273 | B18: BR-273 | C18: Validation - Called Service Outcome | D18: P1 - Critical | E18: PASS | F18: Yes | G18: [OK] successful creation is reported (organizations created counter moves) | [OK] the organisation's output fields are populated in the load output
A19: TC-BR-369 | B19: BR-369 | C19: Validation - Called Service Outcome | D19: P1 - Critical | E19: PASS | F19: Yes | G19: [OK] the appointment is created successfully | [OK] the enriched output record (with its resolved Allstate id) reaches the load output
A20: TC-BR-377 | B20: BR-377 | C20: Validation - Activity Extraction | D20: P1 - Critical | E20: PASS | F20: Yes | G20: [OK] day1 bundle committed: one person (shared SSN) holds two real contracts | [OK] contract B's master row exists and was marked before day2 | [OK] contract A's allstate_id still maps to exactly one contract (no duplicate appointment) | [OK] positive control: contract A's own master row picked up its day2 change (basic4 MISC residentState = CA) | [OK] contract B (no activity of its own) IS pulled in and rebuilt when the processed contract is INVESTMENT_PROFESSIONAL
A21: TC-BR-400 | B21: BR-400 | C21: Validation - Comparison Fields | D21: P1 - Critical | E21: PASS | F21: Yes | G21: [OK] org B's name changed in the master | [OK] orgs A and C (resubmitted with no difference) keep master rows identical to their day1 state
A22: TC-BR-450 | B22: BR-450 | C22: Validation - Table Integrity | D22: P1 - Critical | E22: PASS | F22: Yes | G22: [OK] the BD (a firm kind) carries firm-name detail on its master record | [OK] the individual producer carries a person name, not firm detail, in the same field
A23: TC-BR-451 | B23: BR-451 | C23: Validation - Table Integrity | D23: P1 - Critical | E23: BLOCKED | F23: No | G23: Re-investigated 2026-09-29: confirmed doubly gated - (1) pru_adb.contract.entity_type carries a live CHECK constraint restricting it to exactly BROKER_DEALER/LICENSED_LIFE_ENTITY/HOUSE_ACCOUNT/INVESTMENT_PROFESSIONAL, and (2) BR-064's own upstream HR1 validation independently refuses (C0716) any entity type outside that same set before a contract is ever created. An entity type outside the four recognised kinds can never reach the master-build routine via any feed input. Genuinely unreachable, confirmed via both the DB constraint and the upstream validation rule, not just untested.
A24: TC-BR-006 | B24: BR-006 | C24: Restart and Recovery | D24: P3 - Medium | E24: BLOCKED | F24: No | G24: Requires access to the application server's own filesystem, process control, alternate trigger mechanisms (folder drop, HTTP endpoint, rescan cron), or infrastructure configuration (backup/PITR) - none of which this browser-driven Playwright framework can reach. Verify manually with the dev/ops team. [Reviewed post-DB-cleanup, 2026-09-26: this blocker was never about DB content/state (it is a tooling, unit-test, filesystem, source-code-access, or artifact-capture limitation) - a clean DB does not change it. Not re-run live, since no DB-state change could affect this outcome.] [Re-checked 2026-09-29 against the BRD's own full rule text: still genuinely blocked - no new technique applies.]
A25: TC-BR-007 | B25: BR-007 | C25: Restart and Recovery | D25: P3 - Medium | E25: PASS | F25: Yes | G25: [OK] re-submitting the same file with restart checked does not silently resume from a no-longer-applicable position - the bundle is rolled back/skipped, not re-committed
A26: TC-BR-016 | B26: BR-016 | C26: Firm Entity Validation | D26: P3 - Medium | E26: PASS | F26: Yes | G26: [OK] a blank correspondence address on the first BD firm rejects the whole bundle: LNAERROR contains a B0608 line naming this BD | [OK] an out-of-set resident state value ('ZZ') rejects the whole bundle: LNAERROR contains a B0606 line naming this BD | [OK] a valid control bundle in the same file still commits normally: no error line in LNAERROR names it at all (the run itself isn't failing wholesale) | H26: DEF-RDMS-BRV4-001 - Not a defect; Closed - QA retest PASS (B0606) DEF-RDMS-BRV4-015 - Not a defect; Closed - confirmed via corrected TC
A27: TC-BR-019 | B27: BR-019 | C27: Organisation Creation | D27: P3 - Medium | E27: PASS | F27: Yes | G27: [OK] the valid bundle commits successfully | [OK] the invalid-first-firm bundle is rejected wholesale | [OK] the rejected bundle's BD identifier appears in LNAERROR (C0716, entity type invalid) | [OK] the producer beneath the failed firm is itself rejected (F0113, no functional manager found) - confirmed live: this app rejects such a producer directly in LNAERROR, not via ADBSKIP | [OK] the valid bundle's producer is committed to the load output
A28: TC-BR-020 | B28: BR-020 | C28: Organisation Creation | D28: P3 - Medium | E28: PASS | F28: Yes | G28: [OK] exactly one organization row for the BD org code | [OK] LLE linked to that org via BD_TO_LLE node_relationship
A29: TC-BR-022 | B29: BR-022 | C29: Activity Extraction | D29: P3 - Medium | E29: PASS | F29: Yes | G29: [OK] ALLSTATE-purpose activity reached the master (crd_number updated) | [OK] activity stamped with a non-ALLSTATE purpose_code ('OTHERPART') still reaches the master and updates crd_number - it is NOT filtered out the way this rule describes
A30: TC-BR-023 | B30: BR-023 | C30: Activity Extraction | D30: P3 - Medium | E30: PASS | F30: Yes | G30: [OK] activity posted interleaved by real timestamp (A, B, A, B) is nonetheless returned by the rule's own prescribed query (ordered by contract code, subject, activity_ts) with each contract's rows contiguous, never spread across the result
A31: TC-BR-024 | B31: BR-024 | C31: Activity Extraction | D31: P3 - Medium | E31: PASS | F31: Yes | G31: [OK] 5-char code routes to organization_record | [OK] 6-char code routes to contract_record
A32: TC-BR-026 | B32: BR-026 | C32: Old and New Comparison | D32: P3 - Medium | E32: PASS | F32: Yes | G32: [OK] Confirmed by extension: this is a general/meta rule whose own text names concrete examples (BR-389/ORG_STATUS, BR-404/NAME, BR-417/BIRTH_DATE) that are now live-automated and passing via the standalone-update technique (TC-BR-389, TC-BR-404, TC-BR-417). No separate automation surface exists beyond those concrete field-comparison cases.
A33: TC-BR-027 | B33: BR-027 | C33: Old and New Comparison | D33: P3 - Medium | E33: PASS | F33: Yes | G33: [OK] new contract_record row appears, fully populated (no prior comparison)
A34: TC-BR-028 | B34: BR-028 | C34: Old and New Comparison | D34: P3 - Medium | E34: PASS | F34: Yes | G34: [OK] Confirmed by extension: this is a general/meta rule whose own text names concrete examples (BR-389/ORG_STATUS, BR-404/NAME, BR-417/BIRTH_DATE) that are now live-automated and passing via the standalone-update technique (TC-BR-389, TC-BR-404, TC-BR-417). No separate automation surface exists beyond those concrete field-comparison cases.
A35: TC-BR-030 | B35: BR-030 | C35: Old and New Comparison | D35: P3 - Medium | E35: BLOCKED | F35: No | G35: Re-investigated 2026-09-29: the rule's own BRD text (prior key/subject id/RMO/region/org type/name carried on the activity record alongside the new values) implies these prior values ARE persisted somewhere observable - but a direct query of the live schema (information_schema.columns across every table in pru_adb and adsi_master) confirms there is NO prior_* column anywhere in this modernised app. The legacy activity record's prior-value fields have no counterpart in pru_adb.activity_log_entry (which carries only the new-side transaction_code/subject_id/timestamp, nothing framed as "prior"). Genuinely not observable - confirmed by direct schema inspection, not just inference from the rule text.
A36: TC-BR-031 | B36: BR-031 | C36: Old and New Comparison | D36: P3 - Medium | E36: PASS | F36: Yes | G36: [OK] day2 (feed date 2026-09-09) and day3 (feed date 2026-09-10) standalone rebuilds both complete (no B0700) | [OK] each cycle (day1 creation, day2 rebuild, day3 rebuild) writes its own activity_log_entry row stamped with THAT cycle's own processing date, not the other cycles' dates and not the real wall-clock date this test actually ran on
A37: TC-BR-034 | B37: BR-034 | C37: Contradiction - Batch | D37: P2 - High | E37: PASS | F37: Yes | G37: [OK] record A updated exactly once (its own new crd_number) | [OK] record B updated exactly once (its own new crd_number)
A38: TC-BR-041 | B38: BR-041 | C38: Appointment and Relationship | D38: P3 - Medium | E38: PASS | F38: Yes | G38: [OK] org-level activity recorded for the BD-presented firm
A39: TC-BR-043 | B39: BR-043 | C39: Shared Services | D39: P3 - Medium | E39: PASS | F39: Yes | G39: [OK] cycle with a calendar-impossible date-of-birth (20260231) completes without crashing the run | [OK] the impossible date is not silently stored as a valid date - either rejected (no person row / no birth_date) or caught and logged, never accepted as 2026-02-31 | [OK] a validation signal (error/reject/invalid) appears in the run log for this impossible date, confirming the shared validator catches it rather than a program silently parsing it on its own
A40: TC-BR-050 | B40: BR-050 | C40: History and Change Control | D40: P3 - Medium | E40: PASS | F40: Yes | G40: [OK] all 4 cycles completed | [OK] day1: a brand-new record with a blank home address gets NO HOME row (only the BUSINESS row from the D02 block) - confirmed correct by dev, not "inserted blank" | [OK] day2: a person-only field change (middle name) updates the person and writes NO contract_history/node_relationship_history row - these tables are each scoped to their own specific fields, never "written together" for an arbitrary change | [OK] day2 also inserts the previously-missing HOME row for the first time (the "BR-140 update path") even though its content is still blank | [OK] day3: a resident-state change (a field contract_history IS scoped to) writes a new contract_history row | [OK] day4: a relationship-status change (a field node_relationship_history IS scoped to) writes a new node_relationship_history row | H40: DEF-RDMS-BRV4-016 - Not a defect; Closed - confirmed via corrected TC
...

Sheet Blocked Triage
A1: Suggested Status | B1: Count | C1: What it means
A2: Stays blocked - environment / manual | B2: 12 | C2: Real environment dependency; needs a one-off manual check by dev/ops.
A3: Dev-verified - unit test / code review | B3: 9 | C3: Code-level rule; close with a dev-supplied unit test reference.
A4: Unblock - retest via standalone update feed | B4: 1 | C4: B0700 is correct. Updates go through standalone C / D01+D02 records outside a bundle, not a re-sent bundle.
A5: (resolved this session - moved to PASS/FAIL) | B5: 106 | C5: See final-verdict-report-brv4.xlsx for the full PASS/FAIL breakdown. TC-BR-480 remains blocked after 4 investigated constructions (see its own Claude Notes) - not counted as resolved.
A7: Dev re-check 2026-10-01 (21 still blocked as of 2026-10-02) | B7: Count | C7: TCs
A8: Close - verified by dev test/code | B8: =COUNTIF(BLOCKED!$M:$M,A8) -> 10 | C8: 451, 006, 030, 076, 119, 132, 155, 158, 480
A9: Close - not applicable (no observable behaviour) | B9: =COUNTIF(BLOCKED!$M:$M,A9) -> 10 | C9: 068, 085, 118, 120, 151, 152, 153, 156, 157, 160
A10: Unblock - QA can test via DB seed | B10: =COUNTIF(BLOCKED!$M:$M,A10) -> 1 | C10: 150
A11: Stays blocked - ops/manual check | B11: =COUNTIF(BLOCKED!$M:$M,A11) -> 1 | C11: 159
A12: Total | B12: =SUM(B8:B11) -> 22
A13: Note | B13: All cited tests were in the 2026-09-28/30 full run: 958/958 unit + 206/206 integration green. Only TC-BR-159 still needs a one-off check (mainframe reference corpus). TC-BR-150 was proven on PostgreSQL: 30 seeded rows -> 25 codes.
A15: Testability of the 21 (updated 2026-10-02) | B15: Count | C15: TCs | D15: Proposed Verdict
A16: QA - can test now | B16: =COUNTIF(BLOCKED!$O:$O,A16) -> 1 | C16: 150 | D16: To be tested by QA
A17: QA - needs one extra artifact | B17: =COUNTIF(BLOCKED!$O:$O,A17) -> 1 | C17: - (TC-BR-117 unblocked 2026-10-02: Export/errfile-detectchanges is in the ZIP since dev commit 080c502; automated, now PASS) | D17: -
A18: Dev - unit/integration test | B18: =COUNTIF(BLOCKED!$O:$O,A18) -> 8 | C18: 006, 030, 076, 119, 132, 158, 451, 480 | D18: Verified by dev test
A19: Ops - one-off manual check | B19: =COUNTIF(BLOCKED!$O:$O,A19) -> 3 | C19: 159, 155, 156 | D19: Needs one-off manual check
A20: Nothing to test | B20: =COUNTIF(BLOCKED!$O:$O,A20) -> 9 | C20: 068, 085, 118, 120, 151, 152, 153, 157, 160 | D20: Not Applicable
A21: Total | B21: =SUM(B16:B20) -> 22
A22: Summary | B22: Latest report (2026-10-02): 167 PASS / 1 FAIL / 21 BLOCKED. The only FAIL is TC-BR-436 (DEF-RDMS-BRV4-017, awaiting dev triage). Of the 21 blocked, 9 are Not Applicable, 8 are verified by dev tests, 3 need a one-off ops/owner check, and TC-BR-150 is waiting on dev (INFO log line or close as dev-verified). See the QA Testability 2026-10-02 sheet.

Sheet PASS
A1: TC ID | B1: Rule ID | C1: Topic | D1: Priority | E1: Verdict | F1: Automated? | G1: Explanation | H1: Related Bug(s) (bug log v10)
A2: TC-BR-131 | B2: BR-131 | C2: Contradiction - Batch | D2: P1 - Critical | E2: PASS | F2: Yes | G2: [OK] run still reports COMPLETED despite the blocked master write (silent failure) | [OK] source-of-truth (pru_adb.contract) row WAS created - the failure is specific to the master-write step | [OK] adsi_master.contract_record has NO row for this subject - the blocked write never landed | [OK] master_control.last_updated_date did not advance past its pre-run value | [OK] an ERROR-level log line related to the failed sync was emitted
A3: TC-BR-304 | B3: BR-304 | C3: Validation - Appointment Consistency | D3: P1 - Critical | E3: PASS | F3: Yes | G3: [OK] the move to active writes RA00RA, and node_relationship confirms status 'A' | [OK] the move away from active writes TE00TE, and node_relationship confirms status 'T' | [OK] both transitions are also visible on the master side after HR2 runs: the activated producer's status_code is A and the terminated producer's is T
A4: TC-BR-391 | B4: BR-391 | C4: Validation - Comparison Fields | D4: P1 - Critical | E4: PASS | F4: Yes | G4: [OK] org_elimination_date on the newly built master record differs from the previously-stored value once a real termination date is fed
A5: TC-BR-412 | B5: BR-412 | C5: Validation - Comparison Fields | D5: P1 - Critical | E5: PASS | F5: Yes | G5: [OK] adsi_master.contract_record.final_date now equals the new relationship end date, differing from the pre-termination value
A6: TC-BR-447 | B6: BR-447 | C6: Validation - Table Integrity | D6: P1 - Critical | E6: PASS | F6: Yes | G6: [OK] adsi_master.organization_record.org_status = '9' (eliminated) after terminating the firm's profile | [OK] org_elimination_date is populated and differs from the pre-termination value
A7: TC-BR-464 | B7: BR-464 | C7: Validation - Entity Type Rules | D7: P1 - Critical | E7: PASS | F7: Yes | G7: [OK] terminated-with-date subject has both final_org_code and final_date populated | [OK] inactive-without-date subject (DB-seeded status=I, end date=NULL, then HR2-rebuilt) has final_org_code but NULL final_date | H7: DEF-RDMS-BRV4-005 - Not a defect; Closed - QA retest PASS
A8: TC-BR-476 | B8: BR-476 | C8: Validation - Master Action Routing | D8: P1 - Critical | E8: PASS | F8: Yes | G8: [OK] run with no activity still completes gracefully (not an error) | [OK] master_control.last_updated_date is unchanged or has advanced (never regressed/nulled) by a no-activity cycle
A9: TC-BR-482 | B9: BR-482 | C9: Validation - Master Action Routing | D9: P1 - Critical | E9: PASS | F9: Yes | G9: [OK] this firm's own organization_record/contract_record master rows exist at all in adsi_master (checked right after the first, real feed upload, before any DB-seeding) - previously found missing due to a since-fixed poison-row issue (DEF-RDMS-BRV4-013) | [OK] org entry landed in organization_record | [OK] contract entry landed in contract_record | H9: DEF-RDMS-BRV4-013 - Not a defect (test data); Closed - retracted by QA
A10: TC-BR-485 | B10: BR-485 | C10: Validation - Master File Status | D10: P1 - Critical | E10: PASS | F10: Yes | G10: [OK] both contracts sharing the TIN are present in the master
A11: TC-BR-486 | B11: BR-486 | C11: Validation - Master File Status | D11: P1 - Critical | E11: PASS | F11: Yes | G11: [OK] only firm A's own contract_record row changes - firm B's is untouched, proving the shared TIN never causes cross-contamination on an update
A12: TC-BR-125 | B12: BR-125 | C12: Transaction Integrity | D12: P1 - Critical | E12: PASS | F12: Yes | G12: [OK] the faulted bundle is rejected wholesale | [OK] the faulted bundle's BD identifier appears in LNAERROR | [OK] first producer of the failing bundle is set aside with reason 002, not independently rejected | [OK] second producer of the failing bundle is set aside with reason 002, not independently rejected | [OK] the control bundle's producer is committed, proving the failure did not spill over
A13: TC-BR-126 | B13: BR-126 | C13: Transaction Integrity | D13: P1 - Critical | E13: PASS | F13: Yes | G13: [OK] the GOOD standalone record (existing parent on file) is committed: contract row exists, personal field update applied | [OK] the BAD standalone record (parent never on file) leaves no rows at all - rejected on its own merits, independent of the good record | [OK] run log shows all 4 standalone records processed (no whole-file no-op); no INFO-level log line calls out the rejection specifically, though the DB outcome above is correct
A14: TC-BR-128 | B14: BR-128 | C14: Outcome Classification | D14: P1 - Critical | E14: PASS | F14: Yes | G14: [OK] the own-merits-bad producer (D01, SSN 000000000) is refused and appears in LNAERROR | [OK] that producer's D02 is consequentially set aside with reason 002 (not its own fault), distinguishable from the D01's own-merits rejection | [OK] the separate BD (reserved TIN) is refused on its own merits and appears in LNAERROR | [OK] that BD's own-merits rejection is in LNAERROR only, never ADBSKIP - the three outcomes stay distinguishable
A15: TC-BR-134 | B15: BR-134 | C15: Appointment and Relationship | D15: P1 - Critical | E15: PASS | F15: Yes | G15: [OK] day1 (real appointment under firm X) committed | [OK] the real appointment under firm X exists (precondition) | [OK] BA decision pending (DEF-RDMS-BRV4-002): whether a type-H profile under firm Y creates its own live contract row for an already-appointed person - reported factually, not asserted right/wrong | H15: DEF-RDMS-BRV4-002 - Spec conflict; Blocked - BA decision
A16: TC-BR-142 | B16: BR-142 | C16: Identifier Generation | D16: P1 - Critical | E16: PASS | F16: Yes | G16: [OK] run completed despite the seeded collision (no retry loop hang/error)
A17: TC-BR-143 | B17: BR-143 | C17: Identifier Generation | D17: P1 - Critical | E17: PASS | F17: Yes | G17: [OK] pru_contract_number is 6 chars: fixed leading char + 5 from the no-vowel/no-zero alphabet
A18: TC-BR-273 | B18: BR-273 | C18: Validation - Called Service Outcome | D18: P1 - Critical | E18: PASS | F18: Yes | G18: [OK] successful creation is reported (organizations created counter moves) | [OK] the organisation's output fields are populated in the load output
A19: TC-BR-369 | B19: BR-369 | C19: Validation - Called Service Outcome | D19: P1 - Critical | E19: PASS | F19: Yes | G19: [OK] the appointment is created successfully | [OK] the enriched output record (with its resolved Allstate id) reaches the load output
A20: TC-BR-377 | B20: BR-377 | C20: Validation - Activity Extraction | D20: P1 - Critical | E20: PASS | F20: Yes | G20: [OK] day1 bundle committed: one person (shared SSN) holds two real contracts | [OK] contract B's master row exists and was marked before day2 | [OK] contract A's allstate_id still maps to exactly one contract (no duplicate appointment) | [OK] positive control: contract A's own master row picked up its day2 change (basic4 MISC residentState = CA) | [OK] contract B (no activity of its own) IS pulled in and rebuilt when the processed contract is INVESTMENT_PROFESSIONAL
A21: TC-BR-400 | B21: BR-400 | C21: Validation - Comparison Fields | D21: P1 - Critical | E21: PASS | F21: Yes | G21: [OK] org B's name changed in the master | [OK] orgs A and C (resubmitted with no difference) keep master rows identical to their day1 state
A22: TC-BR-450 | B22: BR-450 | C22: Validation - Table Integrity | D22: P1 - Critical | E22: PASS | F22: Yes | G22: [OK] the BD (a firm kind) carries firm-name detail on its master record | [OK] the individual producer carries a person name, not firm detail, in the same field
A23: TC-BR-007 | B23: BR-007 | C23: Restart and Recovery | D23: P3 - Medium | E23: PASS | F23: Yes | G23: [OK] re-submitting the same file with restart checked does not silently resume from a no-longer-applicable position - the bundle is rolled back/skipped, not re-committed
A24: TC-BR-016 | B24: BR-016 | C24: Firm Entity Validation | D24: P3 - Medium | E24: PASS | F24: Yes | G24: [OK] a blank correspondence address on the first BD firm rejects the whole bundle: LNAERROR contains a B0608 line naming this BD | [OK] an out-of-set resident state value ('ZZ') rejects the whole bundle: LNAERROR contains a B0606 line naming this BD | [OK] a valid control bundle in the same file still commits normally: no error line in LNAERROR names it at all (the run itself isn't failing wholesale) | H24: DEF-RDMS-BRV4-001 - Not a defect; Closed - QA retest PASS (B0606) DEF-RDMS-BRV4-015 - Not a defect; Closed - confirmed via corrected TC
A25: TC-BR-019 | B25: BR-019 | C25: Organisation Creation | D25: P3 - Medium | E25: PASS | F25: Yes | G25: [OK] the valid bundle commits successfully | [OK] the invalid-first-firm bundle is rejected wholesale | [OK] the rejected bundle's BD identifier appears in LNAERROR (C0716, entity type invalid) | [OK] the producer beneath the failed firm is itself rejected (F0113, no functional manager found) - confirmed live: this app rejects such a producer directly in LNAERROR, not via ADBSKIP | [OK] the valid bundle's producer is committed to the load output
A26: TC-BR-020 | B26: BR-020 | C26: Organisation Creation | D26: P3 - Medium | E26: PASS | F26: Yes | G26: [OK] exactly one organization row for the BD org code | [OK] LLE linked to that org via BD_TO_LLE node_relationship
A27: TC-BR-022 | B27: BR-022 | C27: Activity Extraction | D27: P3 - Medium | E27: PASS | F27: Yes | G27: [OK] ALLSTATE-purpose activity reached the master (crd_number updated) | [OK] activity stamped with a non-ALLSTATE purpose_code ('OTHERPART') still reaches the master and updates crd_number - it is NOT filtered out the way this rule describes
A28: TC-BR-023 | B28: BR-023 | C28: Activity Extraction | D28: P3 - Medium | E28: PASS | F28: Yes | G28: [OK] activity posted interleaved by real timestamp (A, B, A, B) is nonetheless returned by the rule's own prescribed query (ordered by contract code, subject, activity_ts) with each contract's rows contiguous, never spread across the result
A29: TC-BR-024 | B29: BR-024 | C29: Activity Extraction | D29: P3 - Medium | E29: PASS | F29: Yes | G29: [OK] 5-char code routes to organization_record | [OK] 6-char code routes to contract_record
A30: TC-BR-026 | B30: BR-026 | C30: Old and New Comparison | D30: P3 - Medium | E30: PASS | F30: Yes | G30: [OK] Confirmed by extension: this is a general/meta rule whose own text names concrete examples (BR-389/ORG_STATUS, BR-404/NAME, BR-417/BIRTH_DATE) that are now live-automated and passing via the standalone-update technique (TC-BR-389, TC-BR-404, TC-BR-417). No separate automation surface exists beyond those concrete field-comparison cases.
A31: TC-BR-027 | B31: BR-027 | C31: Old and New Comparison | D31: P3 - Medium | E31: PASS | F31: Yes | G31: [OK] new contract_record row appears, fully populated (no prior comparison)
A32: TC-BR-028 | B32: BR-028 | C32: Old and New Comparison | D32: P3 - Medium | E32: PASS | F32: Yes | G32: [OK] Confirmed by extension: this is a general/meta rule whose own text names concrete examples (BR-389/ORG_STATUS, BR-404/NAME, BR-417/BIRTH_DATE) that are now live-automated and passing via the standalone-update technique (TC-BR-389, TC-BR-404, TC-BR-417). No separate automation surface exists beyond those concrete field-comparison cases.
A33: TC-BR-031 | B33: BR-031 | C33: Old and New Comparison | D33: P3 - Medium | E33: PASS | F33: Yes | G33: [OK] day2 (feed date 2026-09-09) and day3 (feed date 2026-09-10) standalone rebuilds both complete (no B0700) | [OK] each cycle (day1 creation, day2 rebuild, day3 rebuild) writes its own activity_log_entry row stamped with THAT cycle's own processing date, not the other cycles' dates and not the real wall-clock date this test actually ran on
A34: TC-BR-034 | B34: BR-034 | C34: Contradiction - Batch | D34: P2 - High | E34: PASS | F34: Yes | G34: [OK] record A updated exactly once (its own new crd_number) | [OK] record B updated exactly once (its own new crd_number)
A35: TC-BR-041 | B35: BR-041 | C35: Appointment and Relationship | D35: P3 - Medium | E35: PASS | F35: Yes | G35: [OK] org-level activity recorded for the BD-presented firm
A36: TC-BR-043 | B36: BR-043 | C36: Shared Services | D36: P3 - Medium | E36: PASS | F36: Yes | G36: [OK] cycle with a calendar-impossible date-of-birth (20260231) completes without crashing the run | [OK] the impossible date is not silently stored as a valid date - either rejected (no person row / no birth_date) or caught and logged, never accepted as 2026-02-31 | [OK] a validation signal (error/reject/invalid) appears in the run log for this impossible date, confirming the shared validator catches it rather than a program silently parsing it on its own
A37: TC-BR-050 | B37: BR-050 | C37: History and Change Control | D37: P3 - Medium | E37: PASS | F37: Yes | G37: [OK] all 4 cycles completed | [OK] day1: a brand-new record with a blank home address gets NO HOME row (only the BUSINESS row from the D02 block) - confirmed correct by dev, not "inserted blank" | [OK] day2: a person-only field change (middle name) updates the person and writes NO contract_history/node_relationship_history row - these tables are each scoped to their own specific fields, never "written together" for an arbitrary change | [OK] day2 also inserts the previously-missing HOME row for the first time (the "BR-140 update path") even though its content is still blank | [OK] day3: a resident-state change (a field contract_history IS scoped to) writes a new contract_history row | [OK] day4: a relationship-status change (a field node_relationship_history IS scoped to) writes a new node_relationship_history row | H37: DEF-RDMS-BRV4-016 - Not a defect; Closed - confirmed via corrected TC
A38: TC-BR-051 | B38: BR-051 | C38: History and Change Control | D38: P3 - Medium | E38: PASS | F38: Yes | G38: [OK] pru_adb.contract.updt_ts stays unset and no new activity row is written for a byte-identical resubmission | H38: DEF-RDMS-BRV4-011 - Valid defect; Fixed - PASS for TC-BR-051/318; TC-BR-319 to re-target
A39: TC-BR-052 | B39: BR-052 | C39: History and Change Control | D39: P3 - Medium | E39: PASS | F39: Yes | G39: [OK] each party gets exactly one new contract_history snapshot for its own contract-level change | [OK] each snapshot carries its own contract's entity_type (firm BROKER_DEALER, producer INVESTMENT_PROFESSIONAL) | [OK] the firm snapshot records the firm's change (residentState -> NY) and the producer snapshot the producer's (residentState -> CA) - neither picks up the other's values
A40: TC-BR-053 | B40: BR-053 | C40: Address Maintenance | D40: P3 - Medium | E40: PASS | F40: Yes | G40: [OK] only the BUSINESS address row is stamped as changed - the MAILING row is untouched
...

Sheet FAIL
A1: TC ID | B1: Rule ID | C1: Topic | D1: Priority | E1: Verdict | F1: Automated? | G1: Explanation | H1: Related Bug(s) (bug log v10)
A2: TC-BR-436 | B2: BR-436 | C2: Validation - Comparison Fields | D2: P3 - Medium | E2: FAIL | F2: Yes | G2: [OK] day1 master record holds the mailing section (basic4 ALT_ADDRESS) | [NOT AS EXPECTED] adsi_master.contract_record.basic4_sections element count drops by one (e.g. 3 -> 2) and the ALT_ADDRESS section is gone | H2: DEF-RDMS-BRV4-017 - Needs investigation; Open - awaiting dev triage

Sheet BLOCKED
A1: TC ID | B1: Rule ID | C1: Topic | D1: Priority | E1: Verdict | F1: Automated? | G1: Explanation | H1: Dev Assessment (2026-09-28) | I1: Unblock Approach | J1: Suggested Status | K1: QA Notes (2026-09-29) | L1: Dev Re-check (2026-10-01) | M1: Final Recommendation | N1: Can It Be Tested? | O1: Who Can Test | P1: How | Q1: Proposed Verdict
A2: TC-BR-451 | B2: BR-451 | C2: Validation - Table Integrity | D2: P1 - Critical | E2: BLOCKED | F2: No | G2: Verification method relies on opening the ADSIMSTR mainframe-vs-Java comparator HTML file and/or a specific dated reference SQLDUMP. The source workbook itself documents this comparator as unreliable (cannot parse the real COBOL layout, produces mis-sliced records) - not a dependable basis for an automated PASS/FAIL result. Treat as a manual, secondary cross-check only, per the workbook's own guidance (ASM-03). | H2: The blocker is real: it needs server filesystem/process/infra access, an external reference corpus, or the comparator (documented as unreliable). This is not a product defect. | I2: Assign to dev/ops for a one-off manual check, and record the evidence and who ran it. For comparator-based rules, use SQLDUMP/ADSIMSTR field checks instead where possible. | J2: Stays blocked - environment / manual | K2: Re-investigated 2026-09-29. Confirmed doubly gated: (1) pru_adb.contract.entity_type carries a live CHECK constraint restricting it to exactly BROKER_DEALER/LICENSED_LIFE_ENTITY/HOUSE_ACCOUNT/INVESTMENT_PROFESSIONAL, and (2) BR-064's own upstream HR1 validation independently refuses (C0716) any entity type outside that same set before a contract is ever created. An entity type outside the four recognised kinds can never reach the master-build routine via any feed input - confirmed via both the DB constraint and the upstream validation rule. Would need a direct unit test bypassing HR1 entirely, not a live/DB technique. | L2: Agree it is unreachable live - doubly gated, exactly as QA found. Evidence that the gate holds: BundleProcessorImplTest#aFirmRecordWhoseEntityTypeIsUnrecognisedIsAlsoC0716 / #aFirmRecordCarryingEntityTypeIpIsRejectedAsC0716, plus the contract.entity_type CHECK constraint. In Java the entity type is an enum, so a fifth kind cannot exist in memory either; the 'no build, no error' branch has no Java counterpart to reach. | M2: Close - verified by dev test/code | N2: Yes (dev only) | O2: Dev - unit/integration test | P2: The feed validation (C0716) and the DB CHECK constraint block any fifth entity type; covered by BundleProcessorImplTest. | Q2: Verified by dev test
A3: TC-BR-006 | B3: BR-006 | C3: Restart and Recovery | D3: P3 - Medium | E3: BLOCKED | F3: No | G3: Requires access to the application server's own filesystem, process control, alternate trigger mechanisms (folder drop, HTTP endpoint, rescan cron), or infrastructure configuration (backup/PITR) - none of which this browser-driven Playwright framework can reach. Verify manually with the dev/ops team. | H3: The blocker is real: it needs server filesystem/process/infra access, an external reference corpus, or the comparator (documented as unreliable). This is not a product defect. | I3: Assign to dev/ops for a one-off manual check, and record the evidence and who ran it. For comparator-based rules, use SQLDUMP/ADSIMSTR field checks instead where possible. | J3: Stays blocked - environment / manual | K3: Re-checked 2026-09-29 against the BRD's full rule text (restart-from-position: reads a restart record for the exact byte/record position of the last-processed firm/person and resumes there). Genuinely requires killing a run mid-file and inspecting/forcing the restart record's own state, which needs server process control this framework does not have. No live/DB alternative identified. | L3: Restart-from-checkpoint is covered by tests: AllstateFeedIngestionServiceTest#aRestartRunSkipsBundlesAtOrBeforeTheCheckpointedPosition and #aRestartRunWithNoExistingCheckpointProcessesEveryBundle, and BundleProcessorTransactionIT#aCommittedBundleWithARestartContextWritesACheckpointRow and #aRolledBackBundleWithARestartContextWritesNoCheckpointRow. Killing a live run mid-file remains an optional ops drill. | M3: Close - verified by dev test/code | N3: Yes (dev); optional ops drill | O3: Dev - unit/integration test | P3: Covered by the restart/checkpoint tests. Optional live evidence: ops deliberately stops a run mid-file and restarts it. | Q3: Verified by dev test
A4: TC-BR-030 | B4: BR-030 | C4: Old and New Comparison | D4: P3 - Medium | E4: BLOCKED | F4: No | G4: This rule's own text states its condition cannot be independently verified or reproduced through the modernised application: "Where: nowhere persisted. These prior values - prior key, prior subject id, prior RMO, prior region, prior org type code, prior org full name - are pulled from the old master record at the moment of comparison, attached alongside the new values on that same run's activity record, and used right there to work out what changed - then discarded once that step finishes". Verify manually per the rule's own guidance. | H4: Genuinely not observable through the UI/DB/feed framework; the rule describes in-memory or code-level behaviour. QA's reason is correct. It can be closed on developer evidence rather than left BLOCKED: the full unit suite (958 tests) and integration suite (203 tests) were run green on 2026-09-28. | I4: Ask dev to cite the specific test (class#method) or code line for each rule. Record the verdict as 'Verified (unit test)' with that reference instead of BLOCKED. | J4: Dev-verified - unit test / code review | K4: Re-investigated 2026-09-29. The rule's own BRD text implies the prior key/subject id/RMO/region/org type/name are persisted on the activity record alongside the new values - but a direct query of every column in pru_adb and adsi_master (information_schema.columns) confirms there is NO prior_* column anywhere in this modernised schema. pru_adb.activity_log_entry carries only the new-side transaction_code/subject_id/timestamp, nothing framed as "prior". Confirmed genuinely not observable by direct schema inspection, not just by re-reading the rule text - no live/DB alternative exists. | L4: Agree - there is no prior_* column. In Java the prior key/subject id/RMO/region/org type/org name are fields of the in-memory HrActivityRecord built by AdsiChangeDetectionService.compareOne (priorPrimaryKey, priorSubjectId, priorAosRmo, ...) and discarded after the run - which is what the rule says. Covered by AdsiMasterUpdateServiceTest#addsWhenPriorKeyIsBlank / #updatesWhenPriorKeyMatchesCurrentRecordKey / #keyChangeToAMissingPriorContractNumberThrowsMasterRecordNotFoundException. | M4: Close - verified by dev test/code | N4: Yes (dev only) | O4: Dev - unit/integration test | P4: The prior values live only in memory on HrActivityRecord; the AdsiMasterUpdateService prior-key tests cover them. | Q4: Verified by dev test
A5: TC-BR-068 | B5: BR-068 | C5: Old and New Comparison | D5: P3 - Medium | E5: BLOCKED | F5: No | G5: Requires access to the application server's own filesystem, process control, alternate trigger mechanisms (folder drop, HTTP endpoint, rescan cron), or infrastructure configuration (backup/PITR) - none of which this browser-driven Playwright framework can reach. Verify manually with the dev/ops team. | H5: The blocker is real: it needs server filesystem/process/infra access, an external reference corpus, or the comparator (documented as unreliable). This is not a product defect. | I5: Assign to dev/ops for a one-off manual check, and record the evidence and who ran it. For comparator-based rules, use SQLDUMP/ADSIMSTR field checks instead where possible. | J5: Stays blocked - environment / manual | K5: Re-checked 2026-09-29 against the BRD's full rule text (the comparison and the master update share no state except a single activity file - an internal COBOL-program-boundary claim). This is an architectural/internal-interface fact, not independently checkable by feeding data and observing DB state. No live/DB alternative identified. | L5: Architectural statement. In Java, detectChanges hands its List<HrActivityRecord> straight to AdsiMasterUpdateService.applyActivity (HrMasterSyncRunner.run), and the prior state is read from adsi_master - no other shared state. Covered by HrMasterSyncRunnerTest#passesTheStoresActualLastUpdatedDateAsThePriorMasterDateNotYesterday. | M5: Close - not applicable (no observable behaviour) | N5: No | O5: Nothing to test | P5: Architecture statement (handoff between stages); no behaviour to observe. | Q5: Not Applicable
A6: TC-BR-076 | B6: BR-076 | C6: Contradiction - Batch | D6: P2 - High | E6: BLOCKED | F6: No | G6: Verification method relies on opening the ADSIMSTR mainframe-vs-Java comparator HTML file and/or a specific dated reference SQLDUMP. The source workbook itself documents this comparator as unreliable (cannot parse the real COBOL layout, produces mis-sliced records) - not a dependable basis for an automated PASS/FAIL result. Treat as a manual, secondary cross-check only, per the workbook's own guidance (ASM-03). | H6: The blocker is real: it needs server filesystem/process/infra access, an external reference corpus, or the comparator (documented as unreliable). This is not a product defect. | I6: Assign to dev/ops for a one-off manual check, and record the evidence and who ran it. For comparator-based rules, use SQLDUMP/ADSIMSTR field checks instead where possible. | J6: Stays blocked - environment / manual | K6: Re-investigated 2026-09-29. Confirmed via the BRD's own COBOL excerpt (2000-PROCESS-PARA) that PROCESS-ID is an internal parameter passed to the master-build service by its OWN CALLER (another internal batch step) - there is no feed field or externally reachable input that selects it. Every path this framework can drive (feed upload, standalone update) always supplies a valid organisation-or-contract marker. Genuinely unreachable via any external input - would need a direct internal service-method invocation (e.g. a dev-side unit test calling the build routine with a bogus PROCESS-ID) rather than anything this Playwright/DB framework can drive. | L6: Agree - PROCESS-ID is internal. Java replaces it with the NodeType enum, so an 'unrecognised marker' cannot be represented. An invalid node type is rejected as D002 instead: AdsiChangeDetectionServiceTest#writesD002ForAnInvalidNodeType. | M6: Close - verified by dev test/code | N6: Yes (dev only) | O6: Dev - unit/integration test | P6: An unrecognised process marker cannot be represented (NodeType enum); the D002 test covers invalid node types. | Q6: Verified by dev test
A7: TC-BR-085 | B7: BR-085 | C7: Address Maintenance | D7: P3 - Medium | E7: BLOCKED | F7: No | G7: Verification method relies on opening the ADSIMSTR mainframe-vs-Java comparator HTML file and/or a specific dated reference SQLDUMP. The source workbook itself documents this comparator as unreliable (cannot parse the real COBOL layout, produces mis-sliced records) - not a dependable basis for an automated PASS/FAIL result. Treat as a manual, secondary cross-check only, per the workbook's own guidance (ASM-03). | H7: The blocker is real: it needs server filesystem/process/infra access, an external reference corpus, or the comparator (documented as unreliable). This is not a product defect. | I7: Assign to dev/ops for a one-off manual check, and record the evidence and who ran it. For comparator-based rules, use SQLDUMP/ADSIMSTR field checks instead where possible. | J7: Stays blocked - environment / manual | K7: Re-investigated 2026-09-29. The rule describes a legacy cursor-fetches-first ambiguity when an organisation holds more than one raw address row of the same kind. Direct schema inspection shows pru_adb.address has PRIMARY KEY (ssn_or_contract_number, address_type, purpose_code) - this app cannot hold two rows of the same address kind for one contract; a second incoming address of the same kind always updates the existing row in place (confirmed live via TC-BR-088, now PASS/FAIL on its own separate finding) rather than creating the ambiguous duplicate the rule is about. The scenario is structurally unconstructable in this schema - not just untested, provably impossible to trigger via any feed input. | L7: Agree - provably unconstructable: pru_adb.address PK (ssn_or_contract_number, address_type, purpose_code) permits only one row of a kind, so the 'first row from the cursor' ambiguity cannot arise. | M7: Close - not applicable (no observable behaviour) | N7: No | O7: Nothing to test | P7: Impossible with this schema: the address primary key allows one row per kind. | Q7: Not Applicable
A8: TC-BR-118 | B8: BR-118 | C8: Master Record Service | D8: P3 - Medium | E8: BLOCKED | F8: No | G8: This rule's own text states its condition cannot be independently verified or reproduced through the modernised application: "1. NO DIRECT COUNTERPART: the modernised app manages its own database connections, so no cursor is left open between subjects". Verify manually per the rule's own guidance. | H8: Genuinely not observable through the UI/DB/feed framework; the rule describes in-memory or code-level behaviour. QA's reason is correct. It can be closed on developer evidence rather than left BLOCKED: the full unit suite (958 tests) and integration suite (203 tests) were run green on 2026-09-28. | I8: Ask dev to cite the specific test (class#method) or code line for each rule. Record the verdict as 'Verified (unit test)' with that reference instead of BLOCKED. | J8: Dev-verified - unit test / code review | K8: Re-checked 2026-09-29 against the BRD's full rule text: describes COBOL cursor open/close flags with no counterpart in the modernised app, which manages its own connection pooling. The rule's own text says so explicitly ("NO DIRECT COUNTERPART") - confirmed there is nothing in this architecture to observe. | L8: Agree - the rule itself says there is no direct counterpart (Spring/JDBC manages connections). | M8: Close - not applicable (no observable behaviour) | N8: No | O8: Nothing to test | P8: COBOL cursor handling; no Java equivalent. | Q8: Not Applicable
A9: TC-BR-119 | B9: BR-119 | C9: Run Orchestration and Triggering | D9: P3 - Medium | E9: BLOCKED | F9: No | G9: Requires access to the application server's own filesystem, process control, alternate trigger mechanisms (folder drop, HTTP endpoint, rescan cron), or infrastructure configuration (backup/PITR) - none of which this browser-driven Playwright framework can reach. Verify manually with the dev/ops team. | H9: The blocker is real: it needs server filesystem/process/infra access, an external reference corpus, or the comparator (documented as unreliable). This is not a product defect. | I9: Assign to dev/ops for a one-off manual check, and record the evidence and who ran it. For comparator-based rules, use SQLDUMP/ADSIMSTR field checks instead where possible. | J9: Stays blocked - environment / manual | K9: Re-checked 2026-09-29 against the BRD's full rule text: three trigger routes (folder watch, periodic re-scan, direct HTTP request) must all reach the same processing. Confirming the folder-watch and re-scan paths needs server filesystem access this framework does not have; only the direct-request path is reachable via the UI. No live/DB alternative identified for the other two routes. | L9: All three routes are covered by tests: FolderWatchTriggerIT#aFileLandingInTheDirectoryTriggersACompletedRun (folder watch), LandingDirectoryScannerTest (periodic rescan), IngestionTriggerIT and HttpIngestionTriggerControllerTest (direct HTTP). All reach FeedIngestionLauncher.launch. | M9: Close - verified by dev test/code | N9: Partly QA; rest dev | O9: Dev - unit/integration test | P9: QA can already test the HTTP route through the UI. The folder-watch and rescan routes are covered by FolderWatchTriggerIT / LandingDirectoryScannerTest (they need server access to test live). | Q9: Verified by dev test
A10: TC-BR-120 | B10: BR-120 | C10: Data Platform and Interfaces | D10: P3 - Medium | E10: BLOCKED | F10: No | G10: Requires access to the application server's own filesystem, process control, alternate trigger mechanisms (folder drop, HTTP endpoint, rescan cron), or infrastructure configuration (backup/PITR) - none of which this browser-driven Playwright framework can reach. Verify manually with the dev/ops team. | H10: The blocker is real: it needs server filesystem/process/infra access, an external reference corpus, or the comparator (documented as unreliable). This is not a product defect. | I10: Assign to dev/ops for a one-off manual check, and record the evidence and who ran it. For comparator-based rules, use SQLDUMP/ADSIMSTR field checks instead where possible. | J10: Stays blocked - environment / manual | K10: Re-checked 2026-09-29 against the BRD's full rule text: the inbound file transfer is explicitly out of this process's own responsibility (an external FTP/ops-owned sync process). There is nothing for this application-level framework to test - confirmed as a genuine non-responsibility statement, not an omission. | L10: Agree - file transfer into the landing folder is outside the application (ops/FTP). | M10: Close - not applicable (no observable behaviour) | N10: No | O10: Nothing to test | P10: File transfer into the landing folder is outside the app (ops/FTP). | Q10: Not Applicable
A11: TC-BR-132 | B11: BR-132 | C11: Contradiction - Batch | D11: P2 - High | E11: BLOCKED | F11: No | G11: Trigger condition requires a pre-existing master-DB baseline state (see Isolation Requirement) that this framework cannot seed without direct database access - only a DB fixture, not a feed, can establish it here. Verify manually via: Observed directly against the modernised application (see Verification Basis) | H11: Genuinely not observable through the UI/DB/feed framework; the rule describes in-memory or code-level behaviour. QA's reason is correct. It can be closed on developer evidence rather than left BLOCKED: the full unit suite (958 tests) and integration suite (203 tests) were run green on 2026-09-28. | I11: Ask dev to cite the specific test (class#method) or code line for each rule. Record the verdict as 'Verified (unit test)' with that reference instead of BLOCKED. | J11: Dev-verified - unit test / code review | K11: Re-checked 2026-09-29 against the BRD's full rule text: one section (the trailer) is deliberately excluded from the old-vs-new comparison. The rule's OWN text states "no output of the process would reveal the omission" - this is definitionally unobservable by design, unlike the related hardcoded-field rules (BR-388 etc.) this session did unblock, where the output field itself was observable even though the trigger was hardcoded. No live/DB alternative exists here because the rule's premise is that changing this section produces zero externally visible effect. | L11: Agree it is unobservable by design. Code evidence: AdsiChangeDetectionService.compareContract has no BASIC2 comparison (BASIC2 is filler with no Java field); UTP27901 likewise excludes it. Dev can add a unit test pinning the omission if the BA wants explicit evidence. | M11: Close - verified by dev test/code | N11: Yes (dev only) | O11: Dev - unit/integration test | P11: Unobservable in output by design. Evidence is the code: compareContract has no BASIC2 comparison. Dev can add a pinning unit test if the BA wants one. | Q11: Verified by dev test
A12: TC-BR-150 | B12: BR-150 | C12: Configuration and Retention | D12: P3 - Medium | E12: BLOCKED | F12: No | G12: Requires access to the application server's own filesystem, process control, alternate trigger mechanisms (folder drop, HTTP endpoint, rescan cron), or infrastructure configuration (backup/PITR) - none of which this browser-driven Playwright framework can reach. Verify manually with the dev/ops team. | H12: The blocker is real: it needs server filesystem/process/infra access, an external reference corpus, or the comparator (documented as unreliable). This is not a product defect. | I12: Assign to dev/ops for a one-off manual check, and record the evidence and who ran it. For comparator-based rules, use SQLDUMP/ADSIMSTR field checks instead where possible. | J12: Stays blocked - environment / manual | K12: Re-checked 2026-09-29 against the BRD's full rule text: a configured ceiling (25 transaction codes per item) silently discards codes beyond it. Unlike most other "config value" rules, this ONE may actually be constructible live - feed 26+ genuinely distinct field changes for a single contract in one cycle and confirm only 25 activity rows are retained for it. Not attempted this round due to high construction complexity (reliably forcing 26 distinct detected changes on one contract) for uncertain payoff - flagging this as the one item in this bucket worth a second look if there's appetite for it. | L12: CONSTRUCTIBLE - and much simpler than 26 feed changes. Dev verified 2026-10-01 on PostgreSQL: 30 activity_log_entry rows seeded for one contract on the feed date -> HrActivityExtractService emitted ONE entry carrying exactly 25 transaction codes (the ingestion.max-transaction-codes-per-entity default, HrActivityExtractService:147). QA: use the existing DB-seed technique (activity_ts on the feed date, processed_ts NULL, real contract code), trigger HR2, and check the item carries 25 codes. The 'raise the setting' half is a config change (application.yml) that only dev/ops can make. | M12: Unblock - QA can test via DB seed | N12: Yes | O12: QA - can test now | P12: Seed ~30 activity_log_entry rows for one contract on the feed date (processed_ts NULL), trigger HR2, and check the item carries exactly 25 transaction codes. Already confirmed by dev on PostgreSQL. | Q12: To be tested by QA
